Internal Server Error: /role_add
Traceback (most recent call last):
  File "/home/kajal/.local/lib/python3.10/site-packages/django/core/handlers/exception.py", line 55, in inner
    response = get_response(request)
  File "/home/kajal/.local/lib/python3.10/site-packages/django/core/handlers/base.py", line 197, in _get_response
    response = wrapped_callback(request, *callback_args, **callback_kwargs)
  File "/home/kajal/Desktop/Customer Panel/Customer/Sales/views.py", line 254, in role_add
    permission = roles.objects.filter(id=request.session['user_role']).first()
  File "/home/kajal/.local/lib/python3.10/site-packages/django/contrib/sessions/backends/base.py", line 53, in __getitem__
    return self._session[key]
KeyError: 'user_role'
Internal Server Error: /role_add
Traceback (most recent call last):
  File "/home/kajal/.local/lib/python3.10/site-packages/django/core/handlers/exception.py", line 55, in inner
    response = get_response(request)
  File "/home/kajal/.local/lib/python3.10/site-packages/django/core/handlers/base.py", line 197, in _get_response
    response = wrapped_callback(request, *callback_args, **callback_kwargs)
  File "/home/kajal/Desktop/Customer Panel/Customer/Sales/views.py", line 254, in role_add
    permission = roles.objects.filter(id=request.session['user_role']).first()
  File "/home/kajal/.local/lib/python3.10/site-packages/django/contrib/sessions/backends/base.py", line 53, in __getitem__
    return self._session[key]
KeyError: 'user_role'
Internal Server Error: /role_add
Traceback (most recent call last):
  File "/home/kajal/.local/lib/python3.10/site-packages/django/core/handlers/exception.py", line 55, in inner
    response = get_response(request)
  File "/home/kajal/.local/lib/python3.10/site-packages/django/core/handlers/base.py", line 197, in _get_response
    response = wrapped_callback(request, *callback_args, **callback_kwargs)
  File "/home/kajal/Desktop/Customer Panel/Customer/Sales/views.py", line 370, in role_add
    return render(request, 'roles.html')
  File "/home/kajal/.local/lib/python3.10/site-packages/django/shortcuts.py", line 24, in render
    content = loader.render_to_string(template_name, context, request, using=using)
  File "/home/kajal/.local/lib/python3.10/site-packages/django/template/loader.py", line 61, in render_to_string
    template = get_template(template_name, using=using)
  File "/home/kajal/.local/lib/python3.10/site-packages/django/template/loader.py", line 19, in get_template
    raise TemplateDoesNotExist(template_name, chain=chain)
django.template.exceptions.TemplateDoesNotExist: roles.html
Internal Server Error: /role_add
Traceback (most recent call last):
  File "/home/kajal/.local/lib/python3.10/site-packages/django/template/base.py", line 505, in parse
    compile_func = self.tags[command]
KeyError: 'endblock'

During handling of the above exception, another exception occurred:

Traceback (most recent call last):
  File "/home/kajal/.local/lib/python3.10/site-packages/django/core/handlers/exception.py", line 55, in inner
    response = get_response(request)
  File "/home/kajal/.local/lib/python3.10/site-packages/django/core/handlers/base.py", line 197, in _get_response
    response = wrapped_callback(request, *callback_args, **callback_kwargs)
  File "/home/kajal/Desktop/Customer Panel/Customer/Sales/views.py", line 370, in role_add
    return render(request, 'role.html')
  File "/home/kajal/.local/lib/python3.10/site-packages/django/shortcuts.py", line 24, in render
    content = loader.render_to_string(template_name, context, request, using=using)
  File "/home/kajal/.local/lib/python3.10/site-packages/django/template/loader.py", line 61, in render_to_string
    template = get_template(template_name, using=using)
  File "/home/kajal/.local/lib/python3.10/site-packages/django/template/loader.py", line 15, in get_template
    return engine.get_template(template_name)
  File "/home/kajal/.local/lib/python3.10/site-packages/django/template/backends/django.py", line 33, in get_template
    return Template(self.engine.get_template(template_name), self)
  File "/home/kajal/.local/lib/python3.10/site-packages/django/template/engine.py", line 175, in get_template
    template, origin = self.find_template(template_name)
  File "/home/kajal/.local/lib/python3.10/site-packages/django/template/engine.py", line 157, in find_template
    template = loader.get_template(name, skip=skip)
  File "/home/kajal/.local/lib/python3.10/site-packages/django/template/loaders/cached.py", line 57, in get_template
    template = super().get_template(template_name, skip)
  File "/home/kajal/.local/lib/python3.10/site-packages/django/template/loaders/base.py", line 28, in get_template
    return Template(
  File "/home/kajal/.local/lib/python3.10/site-packages/django/template/base.py", line 154, in __init__
    self.nodelist = self.compile_nodelist()
  File "/home/kajal/.local/lib/python3.10/site-packages/django/template/base.py", line 200, in compile_nodelist
    return parser.parse()
  File "/home/kajal/.local/lib/python3.10/site-packages/django/template/base.py", line 507, in parse
    self.invalid_block_tag(token, command, parse_until)
  File "/home/kajal/.local/lib/python3.10/site-packages/django/template/base.py", line 568, in invalid_block_tag
    raise self.error(
django.template.exceptions.TemplateSyntaxError: Invalid block tag on line 256: 'endblock'. Did you forget to register or load this tag?
Forbidden (CSRF token from POST incorrect.): /roles/add/
Internal Server Error: /roles/add/
Traceback (most recent call last):
  File "/home/kajal/.local/lib/python3.10/site-packages/django/core/handlers/exception.py", line 55, in inner
    response = get_response(request)
  File "/home/kajal/.local/lib/python3.10/site-packages/django/core/handlers/base.py", line 197, in _get_response
    response = wrapped_callback(request, *callback_args, **callback_kwargs)
  File "/home/kajal/Desktop/Customer Panel/Customer/Sales/views.py", line 254, in role_add
    permission = roles.objects.filter(id=request.session['user_role']).first()
  File "/home/kajal/.local/lib/python3.10/site-packages/django/contrib/sessions/backends/base.py", line 53, in __getitem__
    return self._session[key]
KeyError: 'user_role'
Forbidden (CSRF token from POST incorrect.): /
Forbidden (CSRF token from POST incorrect.): /
Internal Server Error: /roles/
Traceback (most recent call last):
  File "/home/kajal/.local/lib/python3.10/site-packages/django/core/handlers/exception.py", line 55, in inner
    response = get_response(request)
  File "/home/kajal/.local/lib/python3.10/site-packages/django/core/handlers/base.py", line 197, in _get_response
    response = wrapped_callback(request, *callback_args, **callback_kwargs)
  File "/home/kajal/Desktop/Customer Panel/Customer/Sales/views.py", line 239, in role_display
    permission = roles.objects.filter(id=request.session['user_role']).first()
  File "/home/kajal/.local/lib/python3.10/site-packages/django/contrib/sessions/backends/base.py", line 53, in __getitem__
    return self._session[key]
KeyError: 'user_role'
Internal Server Error: /logs/
Traceback (most recent call last):
  File "/home/kajal/.local/lib/python3.10/site-packages/django/core/handlers/exception.py", line 55, in inner
    response = get_response(request)
  File "/home/kajal/.local/lib/python3.10/site-packages/django/core/handlers/base.py", line 197, in _get_response
    response = wrapped_callback(request, *callback_args, **callback_kwargs)
  File "/home/kajal/Desktop/Customer Panel/Customer/Sales/views.py", line 207, in view_logs
    permission = roles.objects.filter(id=request.session['user_role']).first()
  File "/home/kajal/.local/lib/python3.10/site-packages/django/contrib/sessions/backends/base.py", line 53, in __getitem__
    return self._session[key]
KeyError: 'user_role'
